Workbook

Sheet Daily
A1: date | B1: weekday | C1: open | D1: cash_rm | E1: duitnow_qr_rm | F1: card_rm | G1: delivery_platform_gross_rm | H1: total_rm | I1: transactions | J1: note
A2: 45931 | B2: Wed | C2: 1 | D2: 335.56 | E2: 231.52 | F2: 71.13 | G2: 156.95 | H2: 795.16 | I2: 81
A3: 45932 | B3: Thu | C3: 1 | D3: 360.16 | E3: 257.44 | F3: 50.34 | G3: 125.13 | H3: 793.07 | I3: 77
A4: 45933 | B4: Fri | C4: 1 | D4: 311.1 | E4: 227.47 | F4: 45.5 | G4: 161.09 | H4: 745.16 | I4: 76
A5: 45934 | B5: Sat | C5: 1 | D5: 415.2 | E5: 311.96 | F5: 81.66 | G5: 189.48 | H5: 998.3 | I5: 110
A6: 45935 | B6: Sun | C6: 1 | D6: 469.36 | E6: 283.1 | F6: 93.15 | G6: 164.3 | H6: 1009.91 | I6: 113
A7: 45936 | B7: Mon | C7: 0 | D7: 0 | E7: 0 | F7: 0 | G7: 0 | H7: 0 | I7: 0 | J7: Closed (Monday)
A8: 45937 | B8: Tue | C8: 1 | D8: 387.33 | E8: 252.36 | F8: 56.26 | G8: 153.72 | H8: 849.67 | I8: 89
A9: 45938 | B9: Wed | C9: 1 | D9: 333.98 | E9: 233.49 | F9: 76.97 | G9: 175.3 | H9: 819.74 | I9: 88
A10: 45939 | B10: Thu | C10: 1 | D10: 333.33 | E10: 238.2 | F10: 66.32 | G10: 105.7 | H10: 743.55 | I10: 80
A11: 45940 | B11: Fri | C11: 1 | D11: 249.91 | E11: 178.65 | F11: 54.12 | G11: 98.12 | H11: 580.8 | I11: 65
A12: 45941 | B12: Sat | C12: 1 | D12: 419.83 | E12: 301.77 | F12: 77.61 | G12: 134.82 | H12: 934.03 | I12: 97
A13: 45942 | B13: Sun | C13: 1 | D13: 410.01 | E13: 288.68 | F13: 61.95 | G13: 219.7 | H13: 980.34 | I13: 105
A14: 45943 | B14: Mon | C14: 0 | D14: 0 | E14: 0 | F14: 0 | G14: 0 | H14: 0 | I14: 0 | J14: Closed (Monday)
A15: 45944 | B15: Tue | C15: 1 | D15: 309.74 | E15: 210.91 | F15: 52.62 | G15: 166.63 | H15: 739.9 | I15: 77
A16: 45945 | B16: Wed | C16: 1 | D16: 308.08 | E16: 208.3 | F16: 50.68 | G16: 150.04 | H16: 717.1 | I16: 80
A17: 45946 | B17: Thu | C17: 1 | D17: 337.64 | E17: 222.1 | F17: 59.98 | G17: 91.21 | H17: 710.93 | I17: 70
A18: 45947 | B18: Fri | C18: 1 | D18: 335.65 | E18: 242.93 | F18: 80.92 | G18: 153.07 | H18: 812.57 | I18: 91
A19: 45948 | B19: Sat | C19: 1 | D19: 502.83 | E19: 343.07 | F19: 97.38 | G19: 171.14 | H19: 1114.42 | I19: 109
A20: 45949 | B20: Sun | C20: 1 | D20: 448.75 | E20: 302.09 | F20: 77.9 | G20: 244 | H20: 1072.74 | I20: 105
A21: 45950 | B21: Mon | C21: 0 | D21: 0 | E21: 0 | F21: 0 | G21: 0 | H21: 0 | I21: 0 | J21: Closed (Monday)
A22: 45951 | B22: Tue | C22: 1 | D22: 278.66 | E22: 192.13 | F22: 64.62 | G22: 125.85 | H22: 661.26 | I22: 67
A23: 45952 | B23: Wed | C23: 1 | D23: 363.04 | E23: 240.55 | F23: 77.5 | G23: 121.32 | H23: 802.41 | I23: 83
A24: 45953 | B24: Thu | C24: 1 | D24: 313.69 | E24: 210.64 | F24: 50.19 | G24: 143.79 | H24: 718.31 | I24: 75
A25: 45954 | B25: Fri | C25: 1 | D25: 317.43 | E25: 230.84 | F25: 53.98 | G25: 108.26 | H25: 710.51 | I25: 73
A26: 45955 | B26: Sat | C26: 1 | D26: 425.73 | E26: 336.34 | F26: 81.96 | G26: 175.57 | H26: 1019.6 | I26: 101
A27: 45956 | B27: Sun | C27: 1 | D27: 438.17 | E27: 333.76 | F27: 98.28 | G27: 201.71 | H27: 1071.92 | I27: 104
A28: 45957 | B28: Mon | C28: 0 | D28: 0 | E28: 0 | F28: 0 | G28: 0 | H28: 0 | I28: 0 | J28: Closed (Monday)
A29: 45958 | B29: Tue | C29: 1 | D29: 354.73 | E29: 231.58 | F29: 61.55 | G29: 169.92 | H29: 817.78 | I29: 85
A30: 45959 | B30: Wed | C30: 1 | D30: 427.32 | E30: 288.98 | F30: 54.08 | G30: 124.18 | H30: 894.56 | I30: 88
A31: 45960 | B31: Thu | C31: 1 | D31: 367.7 | E31: 252.35 | F31: 65.46 | G31: 117.93 | H31: 803.44 | I31: 81
A32: 45961 | B32: Fri | C32: 1 | D32: 324.95 | E32: 239.78 | F32: 62.1 | G32: 167.82 | H32: 794.65 | I32: 85
A33: 45962 | B33: Sat | C33: 1 | D33: 545.84 | E33: 371.06 | F33: 80.83 | G33: 148.25 | H33: 1145.98 | I33: 119
A34: 45963 | B34: Sun | C34: 1 | D34: 453.38 | E34: 310.1 | F34: 68.95 | G34: 126.07 | H34: 958.5 | I34: 106
A35: 45964 | B35: Mon | C35: 0 | D35: 0 | E35: 0 | F35: 0 | G35: 0 | H35: 0 | I35: 0 | J35: Closed (Monday)
A36: 45965 | B36: Tue | C36: 1 | D36: 332.49 | E36: 228.82 | F36: 48.73 | G36: 127.01 | H36: 737.05 | I36: 82
A37: 45966 | B37: Wed | C37: 1 | D37: 343.8 | E37: 227.95 | F37: 44.64 | G37: 127.3 | H37: 743.69 | I37: 82
A38: 45967 | B38: Thu | C38: 1 | D38: 278.92 | E38: 183.99 | F38: 63.63 | G38: 128.3 | H38: 654.84 | I38: 63
A39: 45968 | B39: Fri | C39: 1 | D39: 351.49 | E39: 234.18 | F39: 78.74 | G39: 163.4 | H39: 827.81 | I39: 88
A40: 45969 | B40: Sat | C40: 1 | D40: 402.47 | E40: 240.49 | F40: 67.2 | G40: 135.79 | H40: 845.95 | I40: 85
...

Sheet Monthly
A1: month_start | B1: month_end | C1: open_days | D1: cash_rm | E1: duitnow_qr_rm | F1: card_rm | G1: delivery_gross_rm | H1: total_rm | I1: avg_per_open_day
A2: 45931 | B2: 45961 | C2: =SUMIFS(Daily!C$2:C$366,Daily!A$2:A$366,">="&A2,Daily!A$2:A$366,"<="&B2) -> 27 | D2: =SUMIFS(Daily!D$2:D$366,Daily!A$2:A$366,">="&A2,Daily!A$2:A$366,"<="&B2) -> 9879.88 | E2: =SUMIFS(Daily!E$2:E$366,Daily!A$2:A$366,">="&A2,Daily!A$2:A$366,"<="&B2) -> 6890.99 | F2: =SUMIFS(Daily!F$2:F$366,Daily!A$2:A$366,">="&A2,Daily!A$2:A$366,"<="&B2) -> 1824.21 | G2: =SUMIFS(Daily!G$2:G$366,Daily!A$2:A$366,">="&A2,Daily!A$2:A$366,"<="&B2) -> 4116.75 | H2: =SUMIFS(Daily!H$2:H$366,Daily!A$2:A$366,">="&A2,Daily!A$2:A$366,"<="&B2) -> 22711.83 | I2: =IF(C2=0,0,H2/C2) -> 841.17889
A3: 45962 | B3: 45991 | C3: =SUMIFS(Daily!C$2:C$366,Daily!A$2:A$366,">="&A3,Daily!A$2:A$366,"<="&B3) -> 26 | D3: =SUMIFS(Daily!D$2:D$366,Daily!A$2:A$366,">="&A3,Daily!A$2:A$366,"<="&B3) -> 9874.88 | E3: =SUMIFS(Daily!E$2:E$366,Daily!A$2:A$366,">="&A3,Daily!A$2:A$366,"<="&B3) -> 6816.11 | F3: =SUMIFS(Daily!F$2:F$366,Daily!A$2:A$366,">="&A3,Daily!A$2:A$366,"<="&B3) -> 1728.58 | G3: =SUMIFS(Daily!G$2:G$366,Daily!A$2:A$366,">="&A3,Daily!A$2:A$366,"<="&B3) -> 3826.31 | H3: =SUMIFS(Daily!H$2:H$366,Daily!A$2:A$366,">="&A3,Daily!A$2:A$366,"<="&B3) -> 22245.88 | I3: =IF(C3=0,0,H3/C3) -> 855.61077
A4: 45992 | B4: 46022 | C4: =SUMIFS(Daily!C$2:C$366,Daily!A$2:A$366,">="&A4,Daily!A$2:A$366,"<="&B4) -> 26 | D4: =SUMIFS(Daily!D$2:D$366,Daily!A$2:A$366,">="&A4,Daily!A$2:A$366,"<="&B4) -> 9886.11 | E4: =SUMIFS(Daily!E$2:E$366,Daily!A$2:A$366,">="&A4,Daily!A$2:A$366,"<="&B4) -> 7064.87 | F4: =SUMIFS(Daily!F$2:F$366,Daily!A$2:A$366,">="&A4,Daily!A$2:A$366,"<="&B4) -> 1841.83 | G4: =SUMIFS(Daily!G$2:G$366,Daily!A$2:A$366,">="&A4,Daily!A$2:A$366,"<="&B4) -> 3800.07 | H4: =SUMIFS(Daily!H$2:H$366,Daily!A$2:A$366,">="&A4,Daily!A$2:A$366,"<="&B4) -> 22592.88 | I4: =IF(C4=0,0,H4/C4) -> 868.95692
A5: 46023 | B5: 46053 | C5: =SUMIFS(Daily!C$2:C$366,Daily!A$2:A$366,">="&A5,Daily!A$2:A$366,"<="&B5) -> 27 | D5: =SUMIFS(Daily!D$2:D$366,Daily!A$2:A$366,">="&A5,Daily!A$2:A$366,"<="&B5) -> 10458.3 | E5: =SUMIFS(Daily!E$2:E$366,Daily!A$2:A$366,">="&A5,Daily!A$2:A$366,"<="&B5) -> 7149.98 | F5: =SUMIFS(Daily!F$2:F$366,Daily!A$2:A$366,">="&A5,Daily!A$2:A$366,"<="&B5) -> 1967.3 | G5: =SUMIFS(Daily!G$2:G$366,Daily!A$2:A$366,">="&A5,Daily!A$2:A$366,"<="&B5) -> 4064.95 | H5: =SUMIFS(Daily!H$2:H$366,Daily!A$2:A$366,">="&A5,Daily!A$2:A$366,"<="&B5) -> 23640.53 | I5: =IF(C5=0,0,H5/C5) -> 875.57519
A6: 46054 | B6: 46081 | C6: =SUMIFS(Daily!C$2:C$366,Daily!A$2:A$366,">="&A6,Daily!A$2:A$366,"<="&B6) -> 24 | D6: =SUMIFS(Daily!D$2:D$366,Daily!A$2:A$366,">="&A6,Daily!A$2:A$366,"<="&B6) -> 6847.02 | E6: =SUMIFS(Daily!E$2:E$366,Daily!A$2:A$366,">="&A6,Daily!A$2:A$366,"<="&B6) -> 4725.94 | F6: =SUMIFS(Daily!F$2:F$366,Daily!A$2:A$366,">="&A6,Daily!A$2:A$366,"<="&B6) -> 1278.18 | G6: =SUMIFS(Daily!G$2:G$366,Daily!A$2:A$366,">="&A6,Daily!A$2:A$366,"<="&B6) -> 2768.29 | H6: =SUMIFS(Daily!H$2:H$366,Daily!A$2:A$366,">="&A6,Daily!A$2:A$366,"<="&B6) -> 15619.43 | I6: =IF(C6=0,0,H6/C6) -> 650.80958
A7: 46082 | B7: 46112 | C7: =SUMIFS(Daily!C$2:C$366,Daily!A$2:A$366,">="&A7,Daily!A$2:A$366,"<="&B7) -> 21 | D7: =SUMIFS(Daily!D$2:D$366,Daily!A$2:A$366,">="&A7,Daily!A$2:A$366,"<="&B7) -> 4765.8 | E7: =SUMIFS(Daily!E$2:E$366,Daily!A$2:A$366,">="&A7,Daily!A$2:A$366,"<="&B7) -> 3305.3 | F7: =SUMIFS(Daily!F$2:F$366,Daily!A$2:A$366,">="&A7,Daily!A$2:A$366,"<="&B7) -> 882.48 | G7: =SUMIFS(Daily!G$2:G$366,Daily!A$2:A$366,">="&A7,Daily!A$2:A$366,"<="&B7) -> 1786.92 | H7: =SUMIFS(Daily!H$2:H$366,Daily!A$2:A$366,">="&A7,Daily!A$2:A$366,"<="&B7) -> 10740.5 | I7: =IF(C7=0,0,H7/C7) -> 511.45238
A8: 46113 | B8: 46142 | C8: =SUMIFS(Daily!C$2:C$366,Daily!A$2:A$366,">="&A8,Daily!A$2:A$366,"<="&B8) -> 26 | D8: =SUMIFS(Daily!D$2:D$366,Daily!A$2:A$366,">="&A8,Daily!A$2:A$366,"<="&B8) -> 9954.03 | E8: =SUMIFS(Daily!E$2:E$366,Daily!A$2:A$366,">="&A8,Daily!A$2:A$366,"<="&B8) -> 6833.6 | F8: =SUMIFS(Daily!F$2:F$366,Daily!A$2:A$366,">="&A8,Daily!A$2:A$366,"<="&B8) -> 1782.2 | G8: =SUMIFS(Daily!G$2:G$366,Daily!A$2:A$366,">="&A8,Daily!A$2:A$366,"<="&B8) -> 3966.03 | H8: =SUMIFS(Daily!H$2:H$366,Daily!A$2:A$366,">="&A8,Daily!A$2:A$366,"<="&B8) -> 22535.86 | I8: =IF(C8=0,0,H8/C8) -> 866.76385
A9: 46143 | B9: 46173 | C9: =SUMIFS(Daily!C$2:C$366,Daily!A$2:A$366,">="&A9,Daily!A$2:A$366,"<="&B9) -> 27 | D9: =SUMIFS(Daily!D$2:D$366,Daily!A$2:A$366,">="&A9,Daily!A$2:A$366,"<="&B9) -> 10738.79 | E9: =SUMIFS(Daily!E$2:E$366,Daily!A$2:A$366,">="&A9,Daily!A$2:A$366,"<="&B9) -> 7323.45 | F9: =SUMIFS(Daily!F$2:F$366,Daily!A$2:A$366,">="&A9,Daily!A$2:A$366,"<="&B9) -> 1933.08 | G9: =SUMIFS(Daily!G$2:G$366,Daily!A$2:A$366,">="&A9,Daily!A$2:A$366,"<="&B9) -> 4105.54 | H9: =SUMIFS(Daily!H$2:H$366,Daily!A$2:A$366,">="&A9,Daily!A$2:A$366,"<="&B9) -> 24100.86 | I9: =IF(C9=0,0,H9/C9) -> 892.62444
A10: 46174 | B10: 46203 | C10: =SUMIFS(Daily!C$2:C$366,Daily!A$2:A$366,">="&A10,Daily!A$2:A$366,"<="&B10) -> 25 | D10: =SUMIFS(Daily!D$2:D$366,Daily!A$2:A$366,">="&A10,Daily!A$2:A$366,"<="&B10) -> 9208.85 | E10: =SUMIFS(Daily!E$2:E$366,Daily!A$2:A$366,">="&A10,Daily!A$2:A$366,"<="&B10) -> 6367.56 | F10: =SUMIFS(Daily!F$2:F$366,Daily!A$2:A$366,">="&A10,Daily!A$2:A$366,"<="&B10) -> 1750.07 | G10: =SUMIFS(Daily!G$2:G$366,Daily!A$2:A$366,">="&A10,Daily!A$2:A$366,"<="&B10) -> 3420.98 | H10: =SUMIFS(Daily!H$2:H$366,Daily!A$2:A$366,">="&A10,Daily!A$2:A$366,"<="&B10) -> 20747.46 | I10: =IF(C10=0,0,H10/C10) -> 829.8984
A11: 46204 | B11: 46234 | C11: =SUMIFS(Daily!C$2:C$366,Daily!A$2:A$366,">="&A11,Daily!A$2:A$366,"<="&B11) -> 27 | D11: =SUMIFS(Daily!D$2:D$366,Daily!A$2:A$366,">="&A11,Daily!A$2:A$366,"<="&B11) -> 9980.79 | E11: =SUMIFS(Daily!E$2:E$366,Daily!A$2:A$366,">="&A11,Daily!A$2:A$366,"<="&B11) -> 6971.14 | F11: =SUMIFS(Daily!F$2:F$366,Daily!A$2:A$366,">="&A11,Daily!A$2:A$366,"<="&B11) -> 1805.62 | G11: =SUMIFS(Daily!G$2:G$366,Daily!A$2:A$366,">="&A11,Daily!A$2:A$366,"<="&B11) -> 3912.79 | H11: =SUMIFS(Daily!H$2:H$366,Daily!A$2:A$366,">="&A11,Daily!A$2:A$366,"<="&B11) -> 22670.34 | I11: =IF(C11=0,0,H11/C11) -> 839.64222
A12: 46235 | B12: 46265 | C12: =SUMIFS(Daily!C$2:C$366,Daily!A$2:A$366,">="&A12,Daily!A$2:A$366,"<="&B12) -> 26 | D12: =SUMIFS(Daily!D$2:D$366,Daily!A$2:A$366,">="&A12,Daily!A$2:A$366,"<="&B12) -> 9888.69 | E12: =SUMIFS(Daily!E$2:E$366,Daily!A$2:A$366,">="&A12,Daily!A$2:A$366,"<="&B12) -> 6984.94 | F12: =SUMIFS(Daily!F$2:F$366,Daily!A$2:A$366,">="&A12,Daily!A$2:A$366,"<="&B12) -> 1791.67 | G12: =SUMIFS(Daily!G$2:G$366,Daily!A$2:A$366,">="&A12,Daily!A$2:A$366,"<="&B12) -> 4005.89 | H12: =SUMIFS(Daily!H$2:H$366,Daily!A$2:A$366,">="&A12,Daily!A$2:A$366,"<="&B12) -> 22671.19 | I12: =IF(C12=0,0,H12/C12) -> 871.96885
A13: 46266 | B13: 46295 | C13: =SUMIFS(Daily!C$2:C$366,Daily!A$2:A$366,">="&A13,Daily!A$2:A$366,"<="&B13) -> 26 | D13: =SUMIFS(Daily!D$2:D$366,Daily!A$2:A$366,">="&A13,Daily!A$2:A$366,"<="&B13) -> 9696.51 | E13: =SUMIFS(Daily!E$2:E$366,Daily!A$2:A$366,">="&A13,Daily!A$2:A$366,"<="&B13) -> 6851.62 | F13: =SUMIFS(Daily!F$2:F$366,Daily!A$2:A$366,">="&A13,Daily!A$2:A$366,"<="&B13) -> 1788.44 | G13: =SUMIFS(Daily!G$2:G$366,Daily!A$2:A$366,">="&A13,Daily!A$2:A$366,"<="&B13) -> 3957.75 | H13: =SUMIFS(Daily!H$2:H$366,Daily!A$2:A$366,">="&A13,Daily!A$2:A$366,"<="&B13) -> 22294.32 | I13: =IF(C13=0,0,H13/C13) -> 857.47385
A14: TOTAL | C14: =SUM(C2:C13) -> 308 | D14: =SUM(D2:D13) -> 111179.65 | E14: =SUM(E2:E13) -> 77285.5 | F14: =SUM(F2:F13) -> 20373.66 | G14: =SUM(G2:G13) -> 43732.27 | H14: =SUM(H2:H13) -> 252571.08 | I14: =H14/C14 -> 820.03597
